#VRML_SIM R2019a utf8
WorldInfo {
}
Viewpoint {
  orientation 0.5275478350776167 0.8409193431758535 0.12061484144835265 5.705722424986471
  position -0.4850488506830714 0.5368513043012956 1.2015650652655656
}
TexturedBackground {
}
TexturedBackgroundLight {
}
Floor {
}
Robot {
  translation 0 0.08 0
  children [
    DEF GR_BODY Group {
      children [
        DEF ROBOT_BODY Shape {
          appearance PBRAppearance {
            baseColor 0.9372549019607843 0.1607843137254902 0.1607843137254902
          }
          geometry DEF G_BODY Box {
            size 0.25 0.07 0.1
          }
        }
        Transform {
          translation 0.11 -0.05 0
          children [
            Shape {
              appearance PBRAppearance {
                baseColor 0.9882352941176471 0.9137254901960784 0.30980392156862746
                roughness 1
                metalness 0
              }
              geometry Sphere {
                radius 0.015
              }
            }
          ]
        }
      ]
    }
    DEF WHEEL1_JOINT HingeJoint {
      jointParameters HingeJointParameters {
        axis 0 0 1
        anchor -0.05 0 0.06
      }
      device [
        PositionSensor {
          name "encoder1"
        }
        RotationalMotor {
          name "motor_right"
          maxVelocity 13.1
          maxTorque 0.4903
        }
      ]
      endPoint DEF WHEEL1 Solid {
        translation -0.05 0 0.06
        rotation 1 0 0 1.5707996938995745
        children [
          DEF SH_WHEEL Shape {
            appearance PBRAppearance {
              baseColor 0 0 0
              roughness 1
              metalness 0
            }
            geometry DEF G_WHEEL Cylinder {
              height 0.02
              radius 0.075
            }
          }
        ]
        boundingObject USE G_WHEEL
        physics Physics {
        }
      }
    }
    DEF WHEEL2_JOINT HingeJoint {
      jointParameters HingeJointParameters {
        axis 0 0 1
        anchor -0.05 0 -0.06
      }
      device [
        RotationalMotor {
          name "motor_left"
          maxVelocity 13.1
          maxTorque 0.4903
        }
      ]
      endPoint DEF WHEEL2 Solid {
        translation -0.05 0 -0.06
        rotation 1 0 0 1.5707996938995745
        children [
          USE SH_WHEEL
        ]
        name "solid(1)"
        boundingObject USE G_WHEEL
        physics Physics {
        }
      }
    }
    DistanceSensor {
      translation 0.125 0 0
      children [
        Shape {
          appearance PBRAppearance {
            baseColor 0.9882352941176471 0.9137254901960784 0.30980392156862746
          }
          geometry Box {
            size 0.02 0.01 0.01
          }
        }
      ]
      name "distance_sensor"
      lookupTable [
        0 0 0
        0.02 0 0
        11 1024 0
      ]
      resolution 1
    }
  ]
  boundingObject USE GR_BODY
  physics Physics {
  }
  controller "u2_wp"
}
Solid {
  translation 0.5100000000000001 0.15 0
  children [
    Shape {
      appearance PBRAppearance {
        baseColor 0.6784313725490196 0.4980392156862745 0.6588235294117647
      }
      geometry DEF G_PUPPLEBOX Box {
        size 0.2 0.30000000000000004 0.1
      }
    }
  ]
  boundingObject USE G_PUPPLEBOX
}
